<?xml version="1.0" ?>
<robot name="TandP_URDF" xmlns:xacro="http://www.ros.org/wiki/xacro">

<xacro:include filename="$(find TandP_URDF_description)/urdf/materials.xacro" />
<xacro:include filename="$(find TandP_URDF_description)/urdf/TandP_URDF.trans" />
<xacro:include filename="$(find TandP_URDF_description)/urdf/TandP_URDF.gazebo" />
<link name="base_link">
  <inertial>
    <origin xyz="0.0001845100622695866 -0.27048529128426696 -0.10149358010122299" rpy="0 0 0"/>
    <mass value="0.19985280913819886"/>
    <inertia ixx="0.000194" iyy="0.000194" izz="0.000192" ixy="-0.0" iyz="0.0" ixz="1e-06"/>
  </inertial>
  <visual>
    <origin xyz="0 0 0" rpy="0 0 0"/>
    <geometry>
      <mesh filename="file://$(find TandP_URDF_description)/meshes/base_link.stl" scale="0.001 0.001 0.001"/>
    </geometry>
    <material name="silver"/>
  </visual>
  <collision>
    <origin xyz="0 0 0" rpy="0 0 0"/>
    <geometry>
      <mesh filename="file://$(find TandP_URDF_description)/meshes/base_link.stl" scale="0.001 0.001 0.001"/>
    </geometry>
  </collision>
</link>

<link name="jig_1">
  <inertial>
    <origin xyz="5.453141234135708e-09 0.22451958356493423 7.089573490965578e-10" rpy="0 0 0"/>
    <mass value="0.2404957977531375"/>
    <inertia ixx="0.007197" iyy="2e-06" izz="0.007197" ixy="-0.0" iyz="-0.0" ixz="0.0"/>
  </inertial>
  <visual>
    <origin xyz="0.0 0.3315 -0.0" rpy="0 0 0"/>
    <geometry>
      <mesh filename="file://$(find TandP_URDF_description)/meshes/jig_1.stl" scale="0.001 0.001 0.001"/>
    </geometry>
    <material name="silver"/>
  </visual>
  <collision>
    <origin xyz="0.0 0.3315 -0.0" rpy="0 0 0"/>
    <geometry>
      <mesh filename="file://$(find TandP_URDF_description)/meshes/jig_1.stl" scale="0.001 0.001 0.001"/>
    </geometry>
  </collision>
</link>

<link name="C_1">
  <inertial>
    <origin xyz="0.009127819583737668 0.3353185022812904 0.015337606079264546" rpy="0 0 0"/>
    <mass value="0.7627498608127092"/>
    <inertia ixx="0.025419" iyy="0.000223" izz="0.02547" ixy="-6.3e-05" iyz="-8e-05" ixz="-8e-06"/>
  </inertial>
  <visual>
    <origin xyz="0.01 0.3205 0.0165" rpy="0 0 0"/>
    <geometry>
      <mesh filename="file://$(find TandP_URDF_description)/meshes/C_1.stl" scale="0.001 0.001 0.001"/>
    </geometry>
    <material name="silver"/>
  </visual>
  <collision>
    <origin xyz="0.01 0.3205 0.0165" rpy="0 0 0"/>
    <geometry>
      <mesh filename="file://$(find TandP_URDF_description)/meshes/C_1.stl" scale="0.001 0.001 0.001"/>
    </geometry>
  </collision>
</link>

<link name="B_1">
  <inertial>
    <origin xyz="0.03231922465191705 8.75691299954684e-05 0.014746886997160435" rpy="0 0 0"/>
    <mass value="0.6343642137283538"/>
    <inertia ixx="0.000916" iyy="0.000927" izz="0.000678" ixy="-5e-06" iyz="-4e-06" ixz="-3e-05"/>
  </inertial>
  <visual>
    <origin xyz="0.031 0.2705 -0.0" rpy="0 0 0"/>
    <geometry>
      <mesh filename="file://$(find TandP_URDF_description)/meshes/B_1.stl" scale="0.001 0.001 0.001"/>
    </geometry>
    <material name="silver"/>
  </visual>
  <collision>
    <origin xyz="0.031 0.2705 -0.0" rpy="0 0 0"/>
    <geometry>
      <mesh filename="file://$(find TandP_URDF_description)/meshes/B_1.stl" scale="0.001 0.001 0.001"/>
    </geometry>
  </collision>
</link>

<link name="A_1">
  <inertial>
    <origin xyz="-0.028180944336916466 -4.934640180698224e-06 0.04434916296612579" rpy="0 0 0"/>
    <mass value="0.5957076349917387"/>
    <inertia ixx="0.000928" iyy="0.001784" izz="0.001434" ixy="-0.0" iyz="0.0" ixz="0.000476"/>
  </inertial>
  <visual>
    <origin xyz="-0.0 0.2705 0.071" rpy="0 0 0"/>
    <geometry>
      <mesh filename="file://$(find TandP_URDF_description)/meshes/A_1.stl" scale="0.001 0.001 0.001"/>
    </geometry>
    <material name="silver"/>
  </visual>
  <collision>
    <origin xyz="-0.0 0.2705 0.071" rpy="0 0 0"/>
    <geometry>
      <mesh filename="file://$(find TandP_URDF_description)/meshes/A_1.stl" scale="0.001 0.001 0.001"/>
    </geometry>
  </collision>
</link>

<joint name="A" type="continuous">
  <origin xyz="0.01 -0.011 0.0165" rpy="0 0 0"/>
  <parent link="C_1"/>
  <child link="jig_1"/>
  <axis xyz="-0.0 1.0 -0.0"/>
</joint>

<joint name="B" type="prismatic">
  <origin xyz="0.021 -0.05 -0.0165" rpy="0 0 0"/>
  <parent link="B_1"/>
  <child link="C_1"/>
  <axis xyz="0.0 -1.0 0.0"/>
  <limit upper="0.0" lower="0.0" effort="100" velocity="100"/>
</joint>

<joint name="C" type="continuous">
  <origin xyz="-0.031 0.0 0.071" rpy="0 0 0"/>
  <parent link="A_1"/>
  <child link="B_1"/>
  <axis xyz="1.0 -0.0 0.0"/>
</joint>

<joint name="D" type="continuous">
  <origin xyz="0.0 -0.2705 -0.071" rpy="0 0 0"/>
  <parent link="base_link"/>
  <child link="A_1"/>
  <axis xyz="0.0 0.0 1.0"/>
</joint>

</robot>
